<?xml version="1.0" encoding="utf-8"?>
<!-- This URDF was automatically created by SolidWorks to URDF Exporter! Originally created by
Stephen Brawner (brawner@gmail.com)
     Commit Version: 1.6.0-4-g7f85cfe  Build Version: 1.6.7995.38578
     For more information, please see http://wiki.ros.org/sw_urdf_exporter -->
<robot name="cruzr_s2_v1">

  <mujoco>
    <compiler
      meshdir="../../meshes/cruzr_s2_v1"
      balanceinertia="false"
      discardvisual="false"
      autolimits="true"
      inertiafromgeom="false"
      convexhull="false"
      boundmass="0.0001"
      usethread="true" />
  </mujoco>


  <link name="base_link">
    <inertial>
      <origin xyz="-0.01544497 -0.00000893 0.06234006" rpy="0 0 0" />
      <mass value="96.07762854" />
      <inertia ixx="1.90750568" ixy="-0.11781981" ixz="0.01706062" iyy="3.40515455"
        iyz="-0.00001826" izz="4.66237227" />
    </inertial>
    <visual>
      <origin xyz="0 0 0" rpy="0 0 0" />
      <geometry>
        <mesh filename="/home/lain/robosuite_ws/dual_recovery/robots/meshes/cruzr_s2_v1/base_link.STL" />
      </geometry>
      <material name="">
        <color rgba="0.752941176470588 0.752941176470588 0.752941176470588 1" />
      </material>
    </visual>
    <collision>
      <origin xyz="0 0 0" rpy="0 0 0" />
      <geometry>
        <mesh filename="/home/lain/robosuite_ws/dual_recovery/robots/meshes/cruzr_s2_v1/base_link.STL" />
      </geometry>
    </collision>
  </link>


<link
    name="driven_wheel_left_front_yaw_link">
    <inertial>
      <origin
        xyz="0.00000000 -0.00031481 -0.00722112"
        rpy="0 0 0" />
      <mass
        value="0.70000000" />
      <inertia
        ixx="0.00062424"
        ixy="0.00000000"
        ixz="0.00000000"
        iyy="0.00061021"
        iyz="-0.00001258"
        izz="0.00108405" />
    </inertial>
    <visual>
      <origin
        xyz="0 0 0"
        rpy="0 0 0" />
      <geometry>
        <mesh
          filename="/home/lain/robosuite_ws/dual_recovery/robots/meshes/cruzr_s2_v1/driven_wheel_left_front_yaw_link.STL" />
      </geometry>
      <material
        name="">
        <color
          rgba="0.752941176470588 0.752941176470588 0.752941176470588 1" />
      </material>
    </visual>
    <collision>
      <origin
        xyz="0 0 0"
        rpy="0 0 0" />
      <geometry>
        <mesh
          filename="/home/lain/robosuite_ws/dual_recovery/robots/meshes/cruzr_s2_v1/driven_wheel_left_front_yaw_link.STL" />
      </geometry>
    </collision>
  </link>
  <joint
    name="driven_wheel_left_front_yaw_joint"
    type="continuous">
    <origin
      xyz="0.2395 0.14 -0.026"
      rpy="0 0 -1.5708" />
    <parent
      link="base_link" />
    <child
      link="driven_wheel_left_front_yaw_link" />
    <axis
      xyz="0 0 1" />
  </joint>
  <link
    name="driven_wheel_left_front_roll_left_link">
    <inertial>
      <origin
        xyz="0.00000000 0.00000000 0.00000000"
        rpy="0 0 0" />
      <mass
        value="0.70000000" />
      <inertia
        ixx="0.00029771"
        ixy="0.00000000"
        ixz="0.00000000"
        iyy="0.00029771"
        iyz="0.00000000"
        izz="0.00049361" />
    </inertial>
    <visual>
      <origin
        xyz="0 0 0"
        rpy="0 0 0" />
      <geometry>
        <mesh
          filename="/home/lain/robosuite_ws/dual_recovery/robots/meshes/cruzr_s2_v1/driven_wheel_left_front_roll_left_link.STL" />
      </geometry>
      <material
        name="">
        <color
          rgba="1 1 1 1" />
      </material>
    </visual>
    <collision>
      <origin
        xyz="0 0 0"
        rpy="0 0 0" />
      <geometry>
        <mesh
          filename="/home/lain/robosuite_ws/dual_recovery/robots/meshes/cruzr_s2_v1/driven_wheel_left_front_roll_left_link.STL" />
      </geometry>
    </collision>
  </link>
  <joint
    name="driven_wheel_left_front_roll_left_joint"
    type="continuous">
    <origin
      xyz="-0.016 -0.025 -0.06955"
      rpy="1.5708 0 -1.5708" />
    <parent
      link="driven_wheel_left_front_yaw_link" />
    <child
      link="driven_wheel_left_front_roll_left_link" />
    <axis
      xyz="0 0 1" />
  </joint>
  <link
    name="driven_wheel_left_front_roll_right_link">
        <inertial>
      <origin
        xyz="0.00000000 0.00000000 0.00000000"
        rpy="0 0 0" />
      <mass
        value="0.70000000" />
      <inertia
        ixx="0.00029771"
        ixy="0.00000000"
        ixz="0.00000000"
        iyy="0.00029771"
        iyz="0.00000000"
        izz="0.00049361" />
    </inertial>
    <visual>
      <origin
        xyz="0 0 0"
        rpy="0 0 0" />
      <geometry>
        <mesh
          filename="/home/lain/robosuite_ws/dual_recovery/robots/meshes/cruzr_s2_v1/driven_wheel_left_front_roll_right_link.STL" />
      </geometry>
      <material
        name="">
        <color
          rgba="1 1 1 1" />
      </material>
    </visual>
    <collision>
      <origin
        xyz="0 0 0"
        rpy="0 0 0" />
      <geometry>
        <mesh
          filename="/home/lain/robosuite_ws/dual_recovery/robots/meshes/cruzr_s2_v1/driven_wheel_left_front_roll_right_link.STL" />
      </geometry>
    </collision>
  </link>
  <joint
    name="driven_wheel_left_front_roll_right_joint"
    type="continuous">
    <origin
      xyz="0.016 -0.025 -0.06955"
      rpy="1.5708 0 -1.5708" />
    <parent
      link="driven_wheel_left_front_yaw_link" />
    <child
      link="driven_wheel_left_front_roll_right_link" />
    <axis
      xyz="0 0 1" />
  </joint>
  <link
    name="driven_wheel_left_rear_yaw_link">
        <inertial>
      <origin
        xyz="0.00000000 -0.00031481 -0.00722112"
        rpy="0 0 0" />
      <mass
        value="0.70000000" />
      <inertia
        ixx="0.00062424"
        ixy="0.00000000"
        ixz="0.00000000"
        iyy="0.00061021"
        iyz="-0.00001258"
        izz="0.00108405" />
    </inertial>
    <visual>
      <origin
        xyz="0 0 0"
        rpy="0 0 0" />
      <geometry>
        <mesh
          filename="/home/lain/robosuite_ws/dual_recovery/robots/meshes/cruzr_s2_v1/driven_wheel_left_rear_yaw_link.STL" />
      </geometry>
      <material
        name="">
        <color
          rgba="0.752941176470588 0.752941176470588 0.752941176470588 1" />
      </material>
    </visual>
    <collision>
      <origin
        xyz="0 0 0"
        rpy="0 0 0" />
      <geometry>
        <mesh
          filename="/home/lain/robosuite_ws/dual_recovery/robots/meshes/cruzr_s2_v1/driven_wheel_left_rear_yaw_link.STL" />
      </geometry>
    </collision>
  </link>
  <joint
    name="driven_wheel_left_rear_yaw_joint"
    type="continuous">
    <origin
      xyz="-0.2395 0.14 -0.026"
      rpy="0 0 -1.5708" />
    <parent
      link="base_link" />
    <child
      link="driven_wheel_left_rear_yaw_link" />
    <axis
      xyz="0 0 1" />
  </joint>
  <link
    name="driven_wheel_left_rear_roll_left_link">
        <inertial>
      <origin
        xyz="0.00000000 0.00000000 0.00000000"
        rpy="0 0 0" />
      <mass
        value="0.70000000" />
      <inertia
        ixx="0.00029771"
        ixy="0.00000000"
        ixz="0.00000000"
        iyy="0.00029771"
        iyz="0.00000000"
        izz="0.00049361" />
    </inertial>
    <visual>
      <origin
        xyz="0 0 0"
        rpy="0 0 0" />
      <geometry>
        <mesh
          filename="/home/lain/robosuite_ws/dual_recovery/robots/meshes/cruzr_s2_v1/driven_wheel_left_rear_roll_left_link.STL" />
      </geometry>
      <material
        name="">
        <color
          rgba="1 1 1 1" />
      </material>
    </visual>
    <collision>
      <origin
        xyz="0 0 0"
        rpy="0 0 0" />
      <geometry>
        <mesh
          filename="/home/lain/robosuite_ws/dual_recovery/robots/meshes/cruzr_s2_v1/driven_wheel_left_rear_roll_left_link.STL" />
      </geometry>
    </collision>
  </link>
  <joint
    name="driven_wheel_left_rear_roll_left_joint"
    type="continuous">
    <origin
      xyz="-0.016 -0.025 -0.06955"
      rpy="1.5707963267949 0 -1.5707963267949" />
    <parent
      link="driven_wheel_left_rear_yaw_link" />
    <child
      link="driven_wheel_left_rear_roll_left_link" />
    <axis
      xyz="0 0 1" />
  </joint>
  <link
    name="driven_wheel_left_rear_roll_right_link">
        <inertial>
      <origin
        xyz="0.00000000 0.00000000 0.00000000"
        rpy="0 0 0" />
      <mass
        value="0.70000000" />
      <inertia
        ixx="0.00029771"
        ixy="0.00000000"
        ixz="0.00000000"
        iyy="0.00029771"
        iyz="0.00000000"
        izz="0.00049361" />
    </inertial>
    <visual>
      <origin
        xyz="0 0 0"
        rpy="0 0 0" />
      <geometry>
        <mesh
          filename="/home/lain/robosuite_ws/dual_recovery/robots/meshes/cruzr_s2_v1/driven_wheel_left_rear_roll_right_link.STL" />
      </geometry>
      <material
        name="">
        <color
          rgba="1 1 1 1" />
      </material>
    </visual>
    <collision>
      <origin
        xyz="0 0 0"
        rpy="0 0 0" />
      <geometry>
        <mesh
          filename="/home/lain/robosuite_ws/dual_recovery/robots/meshes/cruzr_s2_v1/driven_wheel_left_rear_roll_right_link.STL" />
      </geometry>
    </collision>
  </link>
  <joint
    name="driven_wheel_left_rear_roll_right_joint"
    type="continuous">
    <origin
      xyz="0.016 -0.025 -0.06955"
      rpy="1.5707963267949 0 -1.5707963267949" />
    <parent
      link="driven_wheel_left_rear_yaw_link" />
    <child
      link="driven_wheel_left_rear_roll_right_link" />
    <axis
      xyz="0 0 1" />
  </joint>
  <link
    name="driven_wheel_right_front_yaw_link">
        <inertial>
      <origin
        xyz="0.00000000 -0.00031481 -0.00722112"
        rpy="0 0 0" />
      <mass
        value="0.70000000" />
      <inertia
        ixx="0.00062424"
        ixy="0.00000000"
        ixz="0.00000000"
        iyy="0.00061021"
        iyz="-0.00001258"
        izz="0.00108405" />
    </inertial>
    <visual>
      <origin
        xyz="0 0 0"
        rpy="0 0 0" />
      <geometry>
        <mesh
          filename="/home/lain/robosuite_ws/dual_recovery/robots/meshes/cruzr_s2_v1/driven_wheel_right_front_yaw_link.STL" />
      </geometry>
      <material
        name="">
        <color
          rgba="0.752941176470588 0.752941176470588 0.752941176470588 1" />
      </material>
    </visual>
    <collision>
      <origin
        xyz="0 0 0"
        rpy="0 0 0" />
      <geometry>
        <mesh
          filename="/home/lain/robosuite_ws/dual_recovery/robots/meshes/cruzr_s2_v1/driven_wheel_right_front_yaw_link.STL" />
      </geometry>
    </collision>
  </link>
  <joint
    name="driven_wheel_right_front_yaw_joint"
    type="continuous">
    <origin
      xyz="0.2395 -0.14 -0.026"
      rpy="0 0 -1.5708" />
    <parent
      link="base_link" />
    <child
      link="driven_wheel_right_front_yaw_link" />
    <axis
      xyz="0 0 1" />
  </joint>
  <link
    name="driven_wheel_right_front_roll_left_link">
        <inertial>
      <origin
        xyz="0.00000000 0.00000000 0.00000000"
        rpy="0 0 0" />
      <mass
        value="0.70000000" />
      <inertia
        ixx="0.00029771"
        ixy="0.00000000"
        ixz="0.00000000"
        iyy="0.00029771"
        iyz="0.00000000"
        izz="0.00049361" />
    </inertial>
    <visual>
      <origin
        xyz="0 0 0"
        rpy="0 0 0" />
      <geometry>
        <mesh
          filename="/home/lain/robosuite_ws/dual_recovery/robots/meshes/cruzr_s2_v1/driven_wheel_right_front_roll_left_link.STL" />
      </geometry>
      <material
        name="">
        <color
          rgba="1 1 1 1" />
      </material>
    </visual>
    <collision>
      <origin
        xyz="0 0 0"
        rpy="0 0 0" />
      <geometry>
        <mesh
          filename="/home/lain/robosuite_ws/dual_recovery/robots/meshes/cruzr_s2_v1/driven_wheel_right_front_roll_left_link.STL" />
      </geometry>
    </collision>
  </link>
  <joint
    name="driven_wheel_right_front_roll_left_joint"
    type="continuous">
    <origin
      xyz="-0.016 -0.025 -0.06955"
      rpy="1.5707963267949 0 -1.5707963267949" />
    <parent
      link="driven_wheel_right_front_yaw_link" />
    <child
      link="driven_wheel_right_front_roll_left_link" />
    <axis
      xyz="0 0 1" />
  </joint>
  <link
    name="driven_wheel_right_front_roll_right_link">
        <inertial>
      <origin
        xyz="0.00000000 0.00000000 0.00000000"
        rpy="0 0 0" />
      <mass
        value="0.70000000" />
      <inertia
        ixx="0.00029771"
        ixy="0.00000000"
        ixz="0.00000000"
        iyy="0.00029771"
        iyz="0.00000000"
        izz="0.00049361" />
    </inertial>
    <visual>
      <origin
        xyz="0 0 0"
        rpy="0 0 0" />
      <geometry>
        <mesh
          filename="/home/lain/robosuite_ws/dual_recovery/robots/meshes/cruzr_s2_v1/driven_wheel_right_front_roll_right_link.STL" />
      </geometry>
      <material
        name="">
        <color
          rgba="1 1 1 1" />
      </material>
    </visual>
    <collision>
      <origin
        xyz="0 0 0"
        rpy="0 0 0" />
      <geometry>
        <mesh
          filename="/home/lain/robosuite_ws/dual_recovery/robots/meshes/cruzr_s2_v1/driven_wheel_right_front_roll_right_link.STL" />
      </geometry>
    </collision>
  </link>
  <joint
    name="driven_wheel_right_front_roll_right_joint"
    type="continuous">
    <origin
      xyz="0.016 -0.025 -0.06955"
      rpy="1.5707963267949 0 -1.5707963267949" />
    <parent
      link="driven_wheel_right_front_yaw_link" />
    <child
      link="driven_wheel_right_front_roll_right_link" />
    <axis
      xyz="0 0 1" />
  </joint>
  <link
    name="driven_wheel_right_rear_yaw_link">
        <inertial>
      <origin
        xyz="0.00000000 -0.00031481 -0.00722112"
        rpy="0 0 0" />
      <mass
        value="0.70000000" />
      <inertia
        ixx="0.00062424"
        ixy="0.00000000"
        ixz="0.00000000"
        iyy="0.00061021"
        iyz="-0.00001258"
        izz="0.00108405" />
    </inertial>
    <visual>
      <origin
        xyz="0 0 0"
        rpy="0 0 0" />
      <geometry>
        <mesh
          filename="/home/lain/robosuite_ws/dual_recovery/robots/meshes/cruzr_s2_v1/driven_wheel_right_rear_yaw_link.STL" />
      </geometry>
      <material
        name="">
        <color
          rgba="0.752941176470588 0.752941176470588 0.752941176470588 1" />
      </material>
    </visual>
    <collision>
      <origin
        xyz="0 0 0"
        rpy="0 0 0" />
      <geometry>
        <mesh
          filename="/home/lain/robosuite_ws/dual_recovery/robots/meshes/cruzr_s2_v1/driven_wheel_right_rear_yaw_link.STL" />
      </geometry>
    </collision>
  </link>
  <joint
    name="driven_wheel_right_rear_yaw_joint"
    type="continuous">
    <origin
      xyz="-0.2395 -0.14 -0.026"
      rpy="0 0 -1.5708" />
    <parent
      link="base_link" />
    <child
      link="driven_wheel_right_rear_yaw_link" />
    <axis
      xyz="0 0 1" />
  </joint>
  <link
    name="driven_wheel_right_rear_roll_left_link">
        <inertial>
      <origin
        xyz="0.00000000 0.00000000 0.00000000"
        rpy="0 0 0" />
      <mass
        value="0.70000000" />
      <inertia
        ixx="0.00029771"
        ixy="0.00000000"
        ixz="0.00000000"
        iyy="0.00029771"
        iyz="0.00000000"
        izz="0.00049361" />
    </inertial>
    <visual>
      <origin
        xyz="0 0 0"
        rpy="0 0 0" />
      <geometry>
        <mesh
          filename="/home/lain/robosuite_ws/dual_recovery/robots/meshes/cruzr_s2_v1/driven_wheel_right_rear_roll_left_link.STL" />
      </geometry>
      <material
        name="">
        <color
          rgba="1 1 1 1" />
      </material>
    </visual>
    <collision>
      <origin
        xyz="0 0 0"
        rpy="0 0 0" />
      <geometry>
        <mesh
          filename="/home/lain/robosuite_ws/dual_recovery/robots/meshes/cruzr_s2_v1/driven_wheel_right_rear_roll_left_link.STL" />
      </geometry>
    </collision>
  </link>
  <joint
    name="driven_wheel_right_rear_roll_left_joint"
    type="continuous">
    <origin
      xyz="-0.016 -0.025 -0.06955"
      rpy="1.5707963267949 0 -1.5707963267949" />
    <parent
      link="driven_wheel_right_rear_yaw_link" />
    <child
      link="driven_wheel_right_rear_roll_left_link" />
    <axis
      xyz="0 0 1" />
  </joint>
  <link
    name="driven_wheel_right_rear_roll_right_link">
        <inertial>
      <origin
        xyz="0.00000000 0.00000000 0.00000000"
        rpy="0 0 0" />
      <mass
        value="0.70000000" />
      <inertia
        ixx="0.00029771"
        ixy="0.00000000"
        ixz="0.00000000"
        iyy="0.00029771"
        iyz="0.00000000"
        izz="0.00049361" />
    </inertial>
    <visual>
      <origin
        xyz="0 0 0"
        rpy="0 0 0" />
      <geometry>
        <mesh
          filename="/home/lain/robosuite_ws/dual_recovery/robots/meshes/cruzr_s2_v1/driven_wheel_right_rear_roll_right_link.STL" />
      </geometry>
      <material
        name="">
        <color
          rgba="1 1 1 1" />
      </material>
    </visual>
    <collision>
      <origin
        xyz="0 0 0"
        rpy="0 0 0" />
      <geometry>
        <mesh
          filename="/home/lain/robosuite_ws/dual_recovery/robots/meshes/cruzr_s2_v1/driven_wheel_right_rear_roll_right_link.STL" />
      </geometry>
    </collision>
  </link>
  <joint
    name="driven_wheel_right_rear_roll_right_joint"
    type="continuous">
    <origin
      xyz="0.016 -0.025 -0.06955"
      rpy="1.5707963267949 0 -1.5707963267949" />
    <parent
      link="driven_wheel_right_rear_yaw_link" />
    <child
      link="driven_wheel_right_rear_roll_right_link" />
    <axis
      xyz="0 0 1" />
  </joint>
  <link
    name="protection_left_front_link">
        <inertial>
      <origin
        xyz="0.00000932 0.00000345 0.00000517"
        rpy="0 0 0" />
      <mass
        value="0.05000000" />
      <inertia
        ixx="0.00001031"
        ixy="0.00000000"
        ixz="0.00000000"
        iyy="0.00001032"
        iyz="0.00000000"
        izz="0.00001656" />
    </inertial>
    <visual>
      <origin
        xyz="0 0 0"
        rpy="0 0 0" />
      <geometry>
        <mesh
          filename="/home/lain/robosuite_ws/dual_recovery/robots/meshes/cruzr_s2_v1/protection_left_front_link.STL" />
      </geometry>
      <material
        name="">
        <color
          rgba="0.752941176470588 0.752941176470588 0.752941176470588 1" />
      </material>
    </visual>
    <collision>
      <origin
        xyz="0 0 0"
        rpy="0 0 0" />
      <geometry>
        <mesh
          filename="/home/lain/robosuite_ws/dual_recovery/robots/meshes/cruzr_s2_v1/protection_left_front_link.STL" />
      </geometry>
    </collision>
  </link>
  <joint
    name="protection_left_front_joint"
    type="continuous">
    <origin
      xyz="0.318 0.03075 -0.097"
      rpy="1.5708 0 -3.1416" />
    <parent
      link="base_link" />
    <child
      link="protection_left_front_link" />
    <axis
      xyz="0 0 1" />
  </joint>
  <link
    name="protection_left_rear_link">
        <inertial>
      <origin
        xyz="0.00000932 0.00000345 0.00000517"
        rpy="0 0 0" />
      <mass
        value="0.05000000" />
      <inertia
        ixx="0.00001031"
        ixy="0.00000000"
        ixz="0.00000000"
        iyy="0.00001032"
        iyz="0.00000000"
        izz="0.00001656" />
    </inertial>
    <visual>
      <origin
        xyz="0 0 0"
        rpy="0 0 0" />
      <geometry>
        <mesh
          filename="/home/lain/robosuite_ws/dual_recovery/robots/meshes/cruzr_s2_v1/protection_left_rear_link.STL" />
      </geometry>
      <material
        name="">
        <color
          rgba="0.752941176470588 0.752941176470588 0.752941176470588 1" />
      </material>
    </visual>
    <collision>
      <origin
        xyz="0 0 0"
        rpy="0 0 0" />
      <geometry>
        <mesh
          filename="/home/lain/robosuite_ws/dual_recovery/robots/meshes/cruzr_s2_v1/protection_left_rear_link.STL" />
      </geometry>
    </collision>
  </link>
  <joint
    name="protection_left_rear_joint"
    type="continuous">
    <origin
      xyz="-0.318 0.03025 -0.097"
      rpy="1.5708 0 3.1416" />
    <parent
      link="base_link" />
    <child
      link="protection_left_rear_link" />
    <axis
      xyz="0 0 1" />
  </joint>
  <link
    name="protection_right_front_link">
        <inertial>
      <origin
        xyz="0.00000932 0.00000345 0.00000517"
        rpy="0 0 0" />
      <mass
        value="0.05000000" />
      <inertia
        ixx="0.00001031"
        ixy="0.00000000"
        ixz="0.00000000"
        iyy="0.00001032"
        iyz="0.00000000"
        izz="0.00001656" />
    </inertial>
    <visual>
      <origin
        xyz="0 0 0"
        rpy="0 0 0" />
      <geometry>
        <mesh
          filename="/home/lain/robosuite_ws/dual_recovery/robots/meshes/cruzr_s2_v1/protection_right_front_link.STL" />
      </geometry>
      <material
        name="">
        <color
          rgba="0.752941176470588 0.752941176470588 0.752941176470588 1" />
      </material>
    </visual>
    <collision>
      <origin
        xyz="0 0 0"
        rpy="0 0 0" />
      <geometry>
        <mesh
          filename="/home/lain/robosuite_ws/dual_recovery/robots/meshes/cruzr_s2_v1/protection_right_front_link.STL" />
      </geometry>
    </collision>
  </link>
  <joint
    name="protection_right_front_joint"
    type="continuous">
    <origin
      xyz="0.318 -0.03075 -0.097"
      rpy="1.5708 0 3.1416" />
    <parent
      link="base_link" />
    <child
      link="protection_right_front_link" />
    <axis
      xyz="0 0 1" />
  </joint>
  <link
    name="protection_right_rear_link">
        <inertial>
      <origin
        xyz="0.00000932 0.00000345 0.00000517"
        rpy="0 0 0" />
      <mass
        value="0.05000000" />
      <inertia
        ixx="0.00001031"
        ixy="0.00000000"
        ixz="0.00000000"
        iyy="0.00001032"
        iyz="0.00000000"
        izz="0.00001656" />
    </inertial>
    <visual>
      <origin
        xyz="0 0 0"
        rpy="0 0 0" />
      <geometry>
        <mesh
          filename="/home/lain/robosuite_ws/dual_recovery/robots/meshes/cruzr_s2_v1/protection_right_rear_link.STL" />
      </geometry>
      <material
        name="">
        <color
          rgba="0.752941176470588 0.752941176470588 0.752941176470588 1" />
      </material>
    </visual>
    <collision>
      <origin
        xyz="0 0 0"
        rpy="0 0 0" />
      <geometry>
        <mesh
          filename="/home/lain/robosuite_ws/dual_recovery/robots/meshes/cruzr_s2_v1/protection_right_rear_link.STL" />
      </geometry>
    </collision>
  </link>
  <joint
    name="protection_right_rear_joint"
    type="continuous">
    <origin
      xyz="-0.318 -0.03025 -0.097"
      rpy="1.5708 0 -3.1416" />
    <parent
      link="base_link" />
    <child
      link="protection_right_rear_link" />
    <axis
      xyz="0 0 1" />
  </joint>
  
  <link name="driving_wheel_left_link">
    <inertial>
      <origin xyz="0.00000000 0.00000000 -0.01061857" rpy="0 0 0" />
      <mass value="11.30000000" />
      <inertia ixx="0.05445598" ixy="0.00000000" ixz="0.00000000" iyy="0.05445598" iyz="0.00000000"
        izz="0.08629618" />
    </inertial>
    <visual>
      <origin xyz="0 0 0" rpy="0 0 0" />
      <geometry>
        <mesh
          filename="/home/lain/robosuite_ws/dual_recovery/robots/meshes/cruzr_s2_v1/driving_wheel_left_link.STL" />
      </geometry>
      <material name="">
        <color rgba="0.898039215686275 0.917647058823529 0.929411764705882 1" />
      </material>
    </visual>
    <collision>
      <origin xyz="0 0 0" rpy="0 0 0" />
      <geometry>
        <mesh
          filename="/home/lain/robosuite_ws/dual_recovery/robots/meshes/cruzr_s2_v1/driving_wheel_left_link.STL" />
      </geometry>
    </collision>
  </link>

  <joint name="driving_wheel_left_joint" type="revolute">
    <origin xyz="0 0.27 0" rpy="1.5708 0 3.1416" />
    <parent link="base_link" />
    <child link="driving_wheel_left_link" />
    <axis xyz="0 0 1" />
    <limit lower="-1e9" upper="1e9" effort="1000" velocity="1000" />
  </joint>

  <link name="driving_wheel_right_link">
    <inertial>
      <origin xyz="0.00000000 0.00000000 0.01061857" rpy="0 0 0" />
      <mass value="11.30000000" />
      <inertia ixx="0.05445598" ixy="0.00000000" ixz="0.00000000" iyy="0.05445598" iyz="0.00000000"
        izz="0.08629618" />
    </inertial>
    <visual>
      <origin xyz="0 0 0" rpy="0 0 0" />
      <geometry>
        <mesh
          filename="/home/lain/robosuite_ws/dual_recovery/robots/meshes/cruzr_s2_v1/driving_wheel_right_link.STL" />
      </geometry>
      <material name="">
        <color rgba="0.898039215686275 0.917647058823529 0.929411764705882 1" />
      </material>
    </visual>
    <collision>
      <origin xyz="0 0 0" rpy="0 0 0" />
      <geometry>
        <mesh
          filename="/home/lain/robosuite_ws/dual_recovery/robots/meshes/cruzr_s2_v1/driving_wheel_right_link.STL" />
      </geometry>
    </collision>
  </link>

  <joint name="driving_wheel_right_joint" type="revolute">
    <origin xyz="0 -0.27 0" rpy="1.5707963267949 0 -3.14159265358979" />
    <parent link="base_link" />
    <child link="driving_wheel_right_link" />
    <axis xyz="0 0 1" />
    <limit lower="-1e9" upper="1e9" effort="1000" velocity="1000" />
  </joint>

  <link name="lifter_base_link">
    <inertial>
      <origin xyz="-0.00947714 0.00000000 -0.04077423" rpy="0 0 0" />
      <mass value="1.33541419" />
      <inertia ixx="0.00441115" ixy="0.00000011" ixz="0.00050178" iyy="0.00956262" iyz="0.00000000"
        izz="0.00845461" />
    </inertial>
    <visual>
      <origin xyz="0 0 0" rpy="0 0 0" />
      <geometry>
        <mesh filename="/home/lain/robosuite_ws/dual_recovery/robots/meshes/cruzr_s2_v1/lifter_base_link.STL" />
      </geometry>
      <material name="">
        <color rgba="0.75294 0.75294 0.75294 1" />
      </material>
    </visual>
    <collision>
      <origin xyz="0 0 0" rpy="0 0 0" />
      <geometry>
        <mesh filename="/home/lain/robosuite_ws/dual_recovery/robots/meshes/cruzr_s2_v1/lifter_base_link.STL" />
      </geometry>
    </collision>
  </link>

  <joint name="base_lifter_joint" type="fixed">
    <origin xyz="0 0 0.281" rpy="0 0 1.5708" />
    <parent link="base_link" />
    <child link="lifter_base_link" />
    <axis xyz="0 0 1" />
  </joint>

  <link name="lifter_pitch_1_link">
    <inertial>
      <origin xyz="0.00000000 0.13800043 -0.01716644" rpy="0 0 0" />
      <mass value="14.51704482" />
      <inertia ixx="0.29212877" ixy="-0.00048517" ixz="0.00000000" iyy="0.04460403"
        iyz="-0.00000011" izz="0.28916709" />
    </inertial>
    <visual>
      <origin xyz="0 0 0" rpy="0 0 0" />
      <geometry>
        <mesh filename="/home/lain/robosuite_ws/dual_recovery/robots/meshes/cruzr_s2_v1/lifter_pitch_1_link.STL" />
      </geometry>
      <material name="">
        <color rgba="0.75294 0.75294 0.75294 1" />
      </material>
    </visual>
    <collision>
      <origin xyz="0 0 0" rpy="0 0 0" />
      <geometry>
        <mesh filename="/home/lain/robosuite_ws/dual_recovery/robots/meshes/cruzr_s2_v1/lifter_pitch_1_link.STL" />
      </geometry>
    </collision>
  </link>

  <joint name="lifter_pitch_1_joint" type="revolute">
    <origin xyz="0 0 0" rpy="1.5708 0 -1.5708" />
    <parent link="lifter_base_link" />
    <child link="lifter_pitch_1_link" />
    <axis xyz="0 0 1" />
    <limit lower="-1.5708" upper="1.5708" effort="0" velocity="0" />
  </joint>

  <link name="lifter_pitch_2_link">
    <inertial>
      <origin xyz="-0.00000361 0.12628301 0.01321268" rpy="0 0 0" />
      <mass value="2.20592286" />
      <inertia ixx="0.02983932" ixy="0.00000053" ixz="-0.00000016" iyy="0.01161597" iyz="0.00004530"
        izz="0.02171850" />
    </inertial>
    <visual>
      <origin xyz="0 0 0" rpy="0 0 0" />
      <geometry>
        <mesh filename="/home/lain/robosuite_ws/dual_recovery/robots/meshes/cruzr_s2_v1/lifter_pitch_2_link.STL" />
      </geometry>
      <material name="">
        <color rgba="0.75294 0.75294 0.75294 1" />
      </material>
    </visual>
    <collision>
      <origin xyz="0 0 0" rpy="0 0 0" />
      <geometry>
        <mesh filename="/home/lain/robosuite_ws/dual_recovery/robots/meshes/cruzr_s2_v1/lifter_pitch_2_link.STL" />
      </geometry>
    </collision>
  </link>

  <joint name="lifter_pitch_2_joint" type="revolute">
    <origin xyz="0 0.276 0" rpy="0 0 0" />
    <parent link="lifter_pitch_1_link" />
    <child link="lifter_pitch_2_link" />
    <axis xyz="0 0 1" />
    <limit lower="-2.6179939" upper="2.6179939" effort="0" velocity="0" />
  </joint>

  <link name="lifter_pitch_3_link">
    <inertial>
      <origin xyz="-0.00002099 0.02041486 -0.00839089" rpy="0 0 0" />
      <mass value="3.13683607" />
      <inertia ixx="0.00931669" ixy="0.00002705" ixz="-0.00002875" iyy="0.00676454"
        iyz="-0.00041424" izz="0.00793986" />
    </inertial>
    <visual>
      <origin xyz="0 0 0" rpy="0 0 0" />
      <geometry>
        <mesh filename="/home/lain/robosuite_ws/dual_recovery/robots/meshes/cruzr_s2_v1/lifter_pitch_3_link.STL" />
      </geometry>
      <material name="">
        <color rgba="0.75294 0.75294 0.75294 1" />
      </material>
    </visual>
    <collision>
      <origin xyz="0 0 0" rpy="0 0 0" />
      <geometry>
        <mesh filename="/home/lain/robosuite_ws/dual_recovery/robots/meshes/cruzr_s2_v1/lifter_pitch_3_link.STL" />
      </geometry>
    </collision>
  </link>

  <joint name="lifter_pitch_3_joint" type="revolute">
    <origin xyz="0 0.255 0" rpy="0 0 0" />
    <parent link="lifter_pitch_2_link" />
    <child link="lifter_pitch_3_link" />
    <axis xyz="0 0 1" />
    <limit lower="-1.5708" upper="1.5708" effort="0" velocity="0" />
  </joint>

  <link name="waist_yaw_link">
    <inertial>
      <origin xyz="0.00012720 -0.00192250 -0.05139278" rpy="0 0 0" />
      <mass value="2.38676288" />
      <inertia ixx="0.00647540" ixy="0.00001199" ixz="-0.00015582" iyy="0.00436934"
        iyz="-0.00025123" izz="0.00610259" />
    </inertial>
    <visual>
      <origin xyz="0 0 0" rpy="0 0 0" />
      <geometry>
        <mesh filename="/home/lain/robosuite_ws/dual_recovery/robots/meshes/cruzr_s2_v1/waist_yaw_link.STL" />
      </geometry>
      <material name="">
        <color rgba="0.75294 0.75294 0.75294 1" />
      </material>
    </visual>
    <collision>
      <origin xyz="0 0 0" rpy="0 0 0" />
      <geometry>
        <mesh filename="/home/lain/robosuite_ws/dual_recovery/robots/meshes/cruzr_s2_v1/waist_yaw_link.STL" />
      </geometry>
    </collision>
  </link>

  <joint name="waist_yaw_joint" type="revolute">
    <origin xyz="0 0.0855 0" rpy="1.5708 0 0" />
    <parent link="lifter_pitch_3_link" />
    <child link="waist_yaw_link" />
    <axis xyz="0 0 1" />
    <limit lower="-2.9670597" upper="2.9670597" effort="0" velocity="0" />
  </joint>

  <link name="torso_link">
    <inertial>
      <origin xyz="-0.00157044 -4.02E-04 -0.06546579" rpy="0 0 0" />
      <mass value="10.06162188" />
      <inertia ixx="0.26154761" ixy="-0.00100056" ixz="1.32E-02" iyy="0.19955424" iyz="-0.00023881"
        izz="1.26E-01" />
    </inertial>
    <visual>
      <origin xyz="0 0 0" rpy="0 0 0" />
      <geometry>
        <mesh filename="/home/lain/robosuite_ws/dual_recovery/robots/meshes/cruzr_s2_v1/torso_link.STL" />
      </geometry>
      <material name="">
        <color rgba="0.75294 0.75294 0.75294 1" />
      </material>
    </visual>
    <collision>
      <origin xyz="0 0 0" rpy="0 0 0" />
      <geometry>
        <mesh filename="/home/lain/robosuite_ws/dual_recovery/robots/meshes/cruzr_s2_v1/torso_link.STL" />
      </geometry>
    </collision>
  </link>

  <joint name="torso_waist_joint" type="fixed">
    <origin xyz="0 -0.0046 -0.37313608" rpy="3.1415926 0 0" />
    <parent link="waist_yaw_link" />
    <child link="torso_link" />
    <axis xyz="0 0 1" />
    <limit lower="0" upper="0" effort="0" velocity="0" />
  </joint>

  <link name="head_base_link">
    <inertial>
      <origin xyz="0 0 0" rpy="0 0 0" />
      <mass value="0.0001" />
      <inertia ixx="1e-10" ixy="0" ixz="0" iyy="1e-10" iyz="0" izz="1e-10" />
    </inertial>
  </link>
  <joint name="head_base_joint" type="fixed">
    <origin xyz="0 0 0.13546" rpy="0 0 0" />
    <parent link="torso_link" />
    <child link="head_base_link" />
    <axis xyz="0 0 1" />
  </joint>

  <link name="head_yaw_link">
    <inertial>
      <origin xyz="0.00023349 -3.98E-05 0.023081" rpy="0 0 0" />
      <mass value="0.21952" />
      <inertia ixx="8.12E-05" ixy="1.01E-06" ixz="-3.2E-07" iyy="6.29E-05" iyz="3.78E-06"
        izz="7.63E-05" />
    </inertial>
    <visual>
      <origin xyz="0 0 0" rpy="0 0 0" />
      <geometry>
        <mesh filename="/home/lain/robosuite_ws/dual_recovery/robots/meshes/cruzr_s2_v1/head_yaw_link.STL" />
      </geometry>
      <material
        name="">
        <color rgba="0.75294 0.75294 0.75294 1" />
      </material>
    </visual>
  </link>
  <joint name="head_yaw_joint" type="revolute">
    <origin xyz="0 0 0.0" rpy="0 0 0" />
    <parent link="head_base_link" />
    <child link="head_yaw_link" />
    <axis xyz="0 0 1" />
    <limit
      lower="-1.658"
      upper="1.658"
      effort="4.5"
      velocity="3.1416" />
  </joint>

  <link name="head_pitch_link">
    <inertial>
      <origin xyz="0.040566 0.1025 -0.00026038" rpy="0 0 0" />
      <mass value="1.069" />
      <inertia ixx="0.0047354" ixy="0.00033437" ixz="-1.26E-05" iyy="0.0045081" iyz="-2.68E-05"
        izz="0.0051857" />
    </inertial>
    <visual>
      <origin xyz="0 0 0" rpy="0 0 0" />
      <geometry>
        <mesh filename="/home/lain/robosuite_ws/dual_recovery/robots/meshes/cruzr_s2_v1/head_pitch_link.STL" />
      </geometry>
      <material name="">
        <color rgba="0.752941176470588 0.752941176470588 0.752941176470588 1" />
      </material>
    </visual>
    <collision>
      <origin xyz="0 0 0" rpy="0 0 0" />
      <geometry>
        <mesh filename="/home/lain/robosuite_ws/dual_recovery/robots/meshes/cruzr_s2_v1/head_pitch_link.STL" />
      </geometry>
    </collision>
  </link>

  <joint name="head_pitch_joint" type="revolute">
    <origin xyz="0 0 0.025" rpy="1.5708 0 0" />
    <parent link="head_yaw_link" />
    <child link="head_pitch_link" />
    <axis xyz="0 0 1" />
    <limit lower="-0.7854" upper="0.5236" effort="4.5" velocity="3.1415926" />
  </joint>

  <link name="L_arm_base_link">
    <inertial>
      <origin xyz="0 0 0" rpy="0 0 0" />
      <mass value="0.0001" />
      <inertia ixx="1e-10" ixy="0" ixz="0" iyy="1e-10" iyz="0" izz="1e-10" />
    </inertial>
  </link>
  <joint name="L_arm_base_joint" type="fixed">
    <origin xyz="0 0.15387 0" rpy="0 -1.74533 1.5708" />
    <parent link="torso_link" />
    <child link="L_arm_base_link" />
    <axis xyz="0 0 1" />
  </joint>

  <link name="L_shoulder_pitch_link">
    <inertial>
      <origin xyz="0.000221 -0.0050932 -0.05263" rpy="0 0 0" />
      <mass value="0.98147" />
      <inertia ixx="0.0011759" ixy="-4.84E-06" ixz="-2.41E-06" iyy="0.0011237" iyz="-3.12E-05"
        izz="0.00090041" />
    </inertial>
    <visual>
      <origin xyz="0 0 0" rpy="0 0 0" />
      <geometry>
        <mesh filename="/home/lain/robosuite_ws/dual_recovery/robots/meshes/cruzr_s2_v1/L_shoulder_pitch_link.STL" />
      </geometry>
      <material
        name="">
        <color rgba="0.75294 0.75294 0.75294 1" />
      </material>
    </visual>
  </link>
  <joint name="L_shoulder_pitch_joint" type="revolute">
    <origin xyz="0 0.0 0" rpy="0 0 0" />
    <parent link="L_arm_base_link" />
    <child link="L_shoulder_pitch_link" />
    <axis xyz="0 0 1" />
    <limit
      lower="-2.8623"
      upper="2.8623"
      effort="80"
      velocity="3.1416" />
  </joint>

  <link name="L_shoulder_roll_link">
    <inertial>
      <origin xyz="-0.036346 0.0019751 -0.0052697" rpy="0 0 0" />
      <mass value="0.53957" />
      <inertia ixx="0.0012305" ixy="-1.9E-05" ixz="0.000107" iyy="0.0018915" iyz="-1.3E-05"
        izz="0.0014298" />
    </inertial>
    <visual>
      <origin xyz="0 0 0" rpy="0 0 0" />
      <geometry>
        <mesh filename="/home/lain/robosuite_ws/dual_recovery/robots/meshes/cruzr_s2_v1/L_shoulder_roll_link.STL" />
      </geometry>
      <material name="">
        <color rgba="0.75294 0.75294 0.75294 1" />
      </material>
    </visual>
    <collision>
      <origin xyz="0 0 0" rpy="0 0 0" />
      <geometry>
        <mesh filename="/home/lain/robosuite_ws/dual_recovery/robots/meshes/cruzr_s2_v1/L_shoulder_roll_link.STL" />
      </geometry>
    </collision>
  </link>

  <joint name="L_shoulder_roll_joint" type="revolute">
    <origin xyz="0 0 -0.06" rpy="-1.5708 0 0" />
    <parent link="L_shoulder_pitch_link" />
    <child link="L_shoulder_roll_link" />
    <axis xyz="0 0 1" />
    <limit lower="-1.885" upper="0.1222" effort="80" velocity="3.1415926" />
  </joint>

  <link name="L_shoulder_yaw_link">
    <inertial>
      <origin xyz="-0.00899 0.00278 0.1286" rpy="0 0 0" />
      <mass value="1.9976" />
      <inertia ixx="0.015656" ixy="5.4E-05" ixz="0.0015653" iyy="0.015768" iyz="-0.000436"
        izz="0.0021057" />
    </inertial>
    <visual>
      <origin xyz="0 0 0" rpy="0 0 0" />
      <geometry>
        <mesh filename="/home/lain/robosuite_ws/dual_recovery/robots/meshes/cruzr_s2_v1/L_shoulder_yaw_link.STL" />
      </geometry>
      <material name="">
        <color rgba="0.752941176470588 0.752941176470588 0.752941176470588 1" />
      </material>
    </visual>
    <collision>
      <origin xyz="0 0 0" rpy="0 0 0" />
      <geometry>
        <mesh filename="/home/lain/robosuite_ws/dual_recovery/robots/meshes/cruzr_s2_v1/L_shoulder_yaw_link.STL" />
      </geometry>
    </collision>
  </link>

  <joint name="L_shoulder_yaw_joint" type="revolute">
    <origin xyz="-0.083 0 0" rpy="-1.5708 0 1.5708" />
    <parent link="L_shoulder_roll_link" />
    <child link="L_shoulder_yaw_link" />
    <axis xyz="0 0 1" />
    <limit lower="-2.9322" upper="2.9322" effort="45" velocity="3.1416" />
  </joint>

  <link name="L_elbow_roll_link">
    <inertial>
      <origin xyz="0.0085304 -0.05741 0.00089275" rpy="0 0 0" />
      <mass value="0.6675" />
      <inertia ixx="0.0025384" ixy="0.00030611" ixz="7.49E-06" iyy="0.0013951" iyz="-3.35E-05"
        izz="0.002205" />
    </inertial>
    <visual>
      <origin xyz="0 0 0" rpy="0 0 0" />
      <geometry>
        <mesh filename="/home/lain/robosuite_ws/dual_recovery/robots/meshes/cruzr_s2_v1/L_elbow_roll_link.STL" />
      </geometry>
      <material name="">
        <color rgba="0.752941176470588 0.752941176470588 0.752941176470588 1" />
      </material>
    </visual>
    <collision>
      <origin xyz="0 0 0" rpy="0 0 0" />
      <geometry>
        <mesh filename="/home/lain/robosuite_ws/dual_recovery/robots/meshes/cruzr_s2_v1/L_elbow_roll_link.STL" />
      </geometry>
    </collision>
  </link>

  <joint name="L_elbow_roll_joint" type="revolute">
    <origin xyz="-0.019993 0 0.213" rpy="-1.5708 0 0" />
    <parent link="L_shoulder_yaw_link" />
    <child link="L_elbow_roll_link" />
    <axis xyz="0 0 1" />
    <limit lower="-2.6529" upper="0.0349" effort="45" velocity="3.1416" />
  </joint>

  <link name="L_elbow_yaw_link">
    <inertial>
      <origin xyz="0.00097407 0.00017933 0.045777" rpy="0 0 0" />
      <mass value="0.87457" />
      <inertia ixx="0.0014384" ixy="3.89E-06" ixz="-5.22E-05" iyy="0.0016363" iyz="7E-07"
        izz="0.00087583" />
    </inertial>
    <visual>
      <origin xyz="0 0 0" rpy="0 0 0" />
      <geometry>
        <mesh filename="/home/lain/robosuite_ws/dual_recovery/robots/meshes/cruzr_s2_v1/L_elbow_yaw_link.STL" />
      </geometry>
      <material name="">
        <color rgba="0.752941176470588 0.752941176470588 0.752941176470588 1" />
      </material>
    </visual>
    <collision>
      <origin xyz="0 0 0" rpy="0 0 0" />
      <geometry>
        <mesh filename="/home/lain/robosuite_ws/dual_recovery/robots/meshes/cruzr_s2_v1/L_elbow_yaw_link.STL" />
      </geometry>
    </collision>
  </link>

  <joint name="L_elbow_yaw_joint" type="revolute">
    <origin xyz="0.019993 -0.10368 0" rpy="1.5708 0 0" />
    <parent link="L_elbow_roll_link" />
    <child link="L_elbow_yaw_link" />
    <axis xyz="0 0 1" />
    <limit lower="-2.9322" upper="2.9322" effort="20" velocity="3.1416" />
  </joint>

  <link name="L_wrist_pitch_link">
    <inertial>
      <origin xyz="-0.038445 -0.0048559 -0.0047721" rpy="0 0 0" />
      <mass value="1.3145" />
      <inertia ixx="0.00090036" ixy="-0.00021851" ixz="0.000227" iyy="0.0027314" iyz="3.05E-05"
        izz="0.0027358" />
    </inertial>
    <visual>
      <origin xyz="0 0 0" rpy="0 0 0" />
      <geometry>
        <mesh filename="/home/lain/robosuite_ws/dual_recovery/robots/meshes/cruzr_s2_v1/L_wrist_pitch_link.STL" />
      </geometry>
      <material name="">
        <color rgba="0.75294 0.75294 0.75294 1" />
      </material>
    </visual>
    <collision>
      <origin xyz="0 0 0" rpy="0 0 0" />
      <geometry>
        <mesh filename="/home/lain/robosuite_ws/dual_recovery/robots/meshes/cruzr_s2_v1/L_wrist_pitch_link.STL" />
      </geometry>
    </collision>
  </link>

  <joint name="L_wrist_pitch_joint" type="revolute">
    <origin xyz="0 0 0.11832" rpy="3.1416 1.5708 0" />
    <parent link="L_elbow_yaw_link" />
    <child link="L_wrist_pitch_link" />
    <axis xyz="0 0 1" />
    <limit lower="-1.658" upper="1.658" effort="20" velocity="3.1416" />
  </joint>

  <link name="L_wrist_roll_link">
    <inertial>
      <origin xyz="-4.59E-06 0.017056 -0.0007487" rpy="0 0 0" />
      <mass value="0.1521" />
      <inertia ixx="0.00027356" ixy="0" ixz="-2E-08" iyy="0.00021546" iyz="-7.68E-06"
        izz="0.00011023" />
    </inertial>
    <visual>
      <origin xyz="0 0 0" rpy="0 0 0" />
      <geometry>
        <mesh filename="/home/lain/robosuite_ws/dual_recovery/robots/meshes/cruzr_s2_v1/L_wrist_roll_link.STL" />
      </geometry>
      <material name="">
        <color rgba="0.752941176470588 0.752941176470588 0.752941176470588 1" />
      </material>
    </visual>
    <collision>
      <origin xyz="0 0 0" rpy="0 0 0" />
      <geometry>
        <mesh filename="/home/lain/robosuite_ws/dual_recovery/robots/meshes/cruzr_s2_v1/L_wrist_roll_link.STL" />
      </geometry>
    </collision>
  </link>

  <joint name="L_wrist_roll_joint" type="revolute">
    <origin xyz="-0.076 0 0" rpy="1.5708 1.5708 3.1416" />
    <parent link="L_wrist_pitch_link" />
    <child link="L_wrist_roll_link" />
    <axis xyz="0 0 1" />
    <limit lower="-2.0245" upper="2.0245" effort="20" velocity="3.1416" />
  </joint>

  <link name="L_sixforce_link">
    <inertial>
      <origin xyz="0.00018615 2.11E-06 -0.011066" rpy="0 0 0" />
      <mass value="0.17" />
      <inertia ixx="3.57E-05" ixy="2.1E-07" ixz="-7.8E-07" iyy="5.03E-05" iyz="6E-08" izz="6.13E-05" />
    </inertial>
    <visual>
      <origin xyz="0 0 0" rpy="0 0 0" />
      <geometry>
        <mesh filename="/home/lain/robosuite_ws/dual_recovery/robots/meshes/cruzr_s2_v1/L_sixforce_link.STL" />
      </geometry>
      <material name="">
        <color rgba="0.698039215686274 0.698039215686274 0.698039215686274 1" />
      </material>
    </visual>
    <collision>
      <origin xyz="0 0 0" rpy="0 0 0" />
      <geometry>
        <mesh filename="/home/lain/robosuite_ws/dual_recovery/robots/meshes/cruzr_s2_v1/L_sixforce_link.STL" />
      </geometry>
    </collision>
  </link>

  <joint name="L_sixforce_joint" type="fixed">
    <origin xyz="0 0.07712 0" rpy="-1.5708 1.5708 0" />
    <parent link="L_wrist_roll_link" />
    <child link="L_sixforce_link" />
    <axis xyz="0 0 0" />
  </joint>
  <link
    name="L_pgc_base_link">
    <inertial>
      <origin
        xyz="-2.46864897094357E-05 0.00101241519250889 0.0801996730801332"
        rpy="0 0 0" />
      <mass
        value="0.512148917198619" />
      <inertia
        ixx="0.000343139195697749"
        ixy="5.50092330982997E-08"
        ixz="-7.25899944571141E-10"
        iyy="0.000325700816895427"
        iyz="2.02321065532314E-06"
        izz="0.000479240940563569" />
    </inertial>
    <visual>
      <origin
        xyz="0 0 0"
        rpy="0 0 0" />
      <geometry>
        <mesh
          filename="/home/lain/robosuite_ws/dual_recovery/robots/meshes/cruzr_s2_v1/pgc_base_link.STL" />
      </geometry>
      <material
        name="">
        <color
          rgba="0.792156862745098 0.819607843137255 0.933333333333333 1" />
      </material>
    </visual>
    <collision>
      <origin
        xyz="0 0 0"
        rpy="0 0 0" />
      <geometry>
        <mesh
          filename="/home/lain/robosuite_ws/dual_recovery/robots/meshes/cruzr_s2_v1/pgc_base_link.STL" />
      </geometry>
    </collision>
  </link>
  <joint name="L_pgc_base_joint" type="fixed">
    <origin xyz="0 0.0 0" rpy="0.0 0 1.5708" />
    <parent link="L_sixforce_link" />
    <child link="L_pgc_base_link" />
    <axis xyz="0 0 0" />
  </joint>
  <link
    name="L_finger1_link">
    <inertial>
      <origin
        xyz="-0.0303858970323615 -0.00381498453417402 -0.00624709492135875"
        rpy="0 0 0" />
      <mass
        value="0.0324239918610202" />
      <inertia
        ixx="2.47261223926961E-06"
        ixy="1.69841580380238E-07"
        ixz="-1.03981478315841E-07"
        iyy="7.85522021789845E-06"
        iyz="-1.88177256558835E-07"
        izz="7.5359499217227E-06" />
    </inertial>
    <visual>
      <origin
        xyz="0 0 0"
        rpy="0 0 0" />
      <geometry>
        <mesh
          filename="/home/lain/robosuite_ws/dual_recovery/robots/meshes/cruzr_s2_v1/finger1_link.STL" />
      </geometry>
      <material
        name="">
        <color
          rgba="0.792156862745098 0.819607843137255 0.933333333333333 1" />
      </material>
    </visual>
    <collision>
      <origin
        xyz="0 0 0"
        rpy="0 0 0" />
      <geometry>
        <mesh
          filename="/home/lain/robosuite_ws/dual_recovery/robots/meshes/cruzr_s2_v1/finger1_link.STL" />
      </geometry>
    </collision>
  </link>
  <joint
    name="L_finger1_joint"
    type="prismatic">
    <origin
      xyz="-0.00016362 -0.018097 0.22048"
      rpy="-1.5708 -1.5708 0" />
    <parent
      link="L_pgc_base_link" />
    <child
      link="L_finger1_link" />
    <axis
      xyz="0 0 1" />
    <limit
      lower="-0.1"
      upper="0.1"
      effort="0"
      velocity="0" />
  </joint>
  <link
    name="L_finger2_link">
    <inertial>
      <origin
        xyz="-0.0303858970296882 -0.00381498453417001 -0.00624709492619996"
        rpy="0 0 0" />
      <mass
        value="0.0324239918610213" />
      <inertia
        ixx="2.47261220318982E-06"
        ixy="1.69841580415508E-07"
        ixz="-1.03981478008923E-07"
        iyy="7.85522021462028E-06"
        iyz="-1.88177256549449E-07"
        izz="7.53594989139987E-06" />
    </inertial>
    <visual>
      <origin
        xyz="0 0 0"
        rpy="0 0 0" />
      <geometry>
        <mesh
          filename="/home/lain/robosuite_ws/dual_recovery/robots/meshes/cruzr_s2_v1/finger2_link.STL" />
      </geometry>
      <material
        name="">
        <color
          rgba="0.792156862745098 0.819607843137255 0.933333333333333 1" />
      </material>
    </visual>
    <collision>
      <origin
        xyz="0 0 0"
        rpy="0 0 0" />
      <geometry>
        <mesh
          filename="/home/lain/robosuite_ws/dual_recovery/robots/meshes/cruzr_s2_v1/finger2_link.STL" />
      </geometry>
    </collision>
  </link>
  <joint
    name="L_finger2_joint"
    type="prismatic">
    <origin
      xyz="0.00013638 0.014376 0.22048"
      rpy="1.5708 -1.5708 0" />
    <parent
      link="L_pgc_base_link" />
    <child
      link="L_finger2_link" />
    <axis
      xyz="0 0 1" />
    <limit
      lower="-0.1"
      upper="0.1"
      effort="0"
      velocity="0" />
  </joint>
  <link name="R_arm_base_link">
    <inertial>
      <origin xyz="0 0 0" rpy="0 0 0" />
      <mass value="0.0001" />
      <inertia ixx="1e-10" ixy="0" ixz="0" iyy="1e-10" iyz="0" izz="1e-10" />
    </inertial>
  </link>
  <joint name="R_arm_base_joint" type="fixed">
    <origin xyz="0 -0.15387 0" rpy="3.1416 -1.39627 1.5708" />
    <parent link="torso_link" />
    <child link="R_arm_base_link" />
    <axis xyz="0 0 1" />
  </joint>
  <link name="R_shoulder_pitch_link">
    <inertial>
      <origin xyz="-8.87E-05 0.0050444 -0.052623" rpy="0 0 0" />
      <mass value="0.98273" />
      <inertia ixx="0.0011778" ixy="-5.21E-06" ixz="-4.64E-06" iyy="0.0011244" iyz="3.15E-05"
        izz="0.00090287" />
    </inertial>
    <visual>
      <origin xyz="0 0 0" rpy="0 0 0" />
      <geometry>
        <mesh filename="/home/lain/robosuite_ws/dual_recovery/robots/meshes/cruzr_s2_v1/R_shoulder_pitch_link.STL" />
      </geometry>
      <material
        name="">
        <color rgba="0.75294 0.75294 0.75294 1" />
      </material>
    </visual>
  </link>
  <joint name="R_shoulder_pitch_joint" type="revolute">
    <origin xyz="0 0.0 0" rpy="0 0 0" />
    <parent link="R_arm_base_link" />
    <child link="R_shoulder_pitch_link" />
    <axis xyz="0 0 1" />
    <limit
      lower="-2.8623"
      upper="2.8623"
      effort="80"
      velocity="3.1416" />
  </joint>

  <link name="R_shoulder_roll_link">
    <inertial>
      <origin xyz="-0.036091 0.0019662 0.0053449" rpy="0 0 0" />
      <mass value="0.5434" />
      <inertia ixx="0.0012461" ixy="-1.87E-05" ixz="-0.000109" iyy="0.001912" iyz="1.3E-05"
        izz="0.0014368" />
    </inertial>
    <visual>
      <origin xyz="0 0 0" rpy="0 0 0" />
      <geometry>
        <mesh filename="/home/lain/robosuite_ws/dual_recovery/robots/meshes/cruzr_s2_v1/R_shoulder_roll_link.STL" />
      </geometry>
      <material name="">
        <color rgba="0.75294 0.75294 0.75294 1" />
      </material>
    </visual>
    <collision>
      <origin xyz="0 0 0" rpy="0 0 0" />
      <geometry>
        <mesh filename="/home/lain/robosuite_ws/dual_recovery/robots/meshes/cruzr_s2_v1/R_shoulder_roll_link.STL" />
      </geometry>
    </collision>
  </link>

  <joint name="R_shoulder_roll_joint" type="revolute">
    <origin xyz="0 0 -0.06" rpy="-1.5708 0 0" />
    <parent link="R_shoulder_pitch_link" />
    <child link="R_shoulder_roll_link" />
    <axis xyz="0 0 1" />
    <limit lower="-1.885" upper="0.1222" effort="80" velocity="3.1416" />
  </joint>

  <link name="R_shoulder_yaw_link">
    <inertial>
      <origin xyz="-0.0090557 -0.0029797 0.12863" rpy="0 0 0" />
      <mass value="1.9965" />
      <inertia ixx="0.015641" ixy="-4.94E-05" ixz="0.0015722" iyy="0.015751" iyz="0.000468"
        izz="0.0021093" />
    </inertial>
    <visual>
      <origin xyz="0 0 0" rpy="0 0 0" />
      <geometry>
        <mesh filename="/home/lain/robosuite_ws/dual_recovery/robots/meshes/cruzr_s2_v1/R_shoulder_yaw_link.STL" />
      </geometry>
      <material name="">
        <color rgba="0.752941176470588 0.752941176470588 0.752941176470588 1" />
      </material>
    </visual>
    <collision>
      <origin xyz="0 0 0" rpy="0 0 0" />
      <geometry>
        <mesh filename="/home/lain/robosuite_ws/dual_recovery/robots/meshes/cruzr_s2_v1/R_shoulder_yaw_link.STL" />
      </geometry>
    </collision>
  </link>

  <joint name="R_shoulder_yaw_joint" type="revolute">
    <origin xyz="-0.083 0 0" rpy="-1.5708 -0.020023 1.5708" />
    <parent link="R_shoulder_roll_link" />
    <child link="R_shoulder_yaw_link" />
    <axis xyz="0 0 1" />
    <limit lower="-2.9322" upper="2.9322" effort="45" velocity="3.1416" />
  </joint>

  <link name="R_elbow_roll_link">
    <inertial>
      <origin xyz="0.0083606 -0.0579 -0.00065816" rpy="0 0 0" />
      <mass value="0.68337" />
      <inertia ixx="0.0025998" ixy="0.00029753" ixz="-5.05E-06" iyy="0.0014326" iyz="2.64E-05"
        izz="0.0022487" />
    </inertial>
    <visual>
      <origin xyz="0 0 0" rpy="0 0 0" />
      <geometry>
        <mesh filename="/home/lain/robosuite_ws/dual_recovery/robots/meshes/cruzr_s2_v1/R_elbow_roll_link.STL" />
      </geometry>
      <material name="">
        <color rgba="0.752941176470588 0.752941176470588 0.752941176470588 1" />
      </material>
    </visual>
    <collision>
      <origin xyz="0 0 0" rpy="0 0 0" />
      <geometry>
        <mesh filename="/home/lain/robosuite_ws/dual_recovery/robots/meshes/cruzr_s2_v1/R_elbow_roll_link.STL" />
      </geometry>
    </collision>
  </link>

  <joint name="R_elbow_roll_joint" type="revolute">
    <origin xyz="-0.019989 -0.00040028 0.213" rpy="-1.5708 0 0.020023" />
    <parent link="R_shoulder_yaw_link" />
    <child link="R_elbow_roll_link" />
    <axis xyz="0 0 1" />
    <limit lower="-2.6529" upper="0.0349" effort="45" velocity="3.1416" />
  </joint>

  <link name="R_elbow_yaw_link">
    <inertial>
      <origin xyz="-0.00097407 -0.00017922 0.045777" rpy="0 0 0" />
      <mass value="0.87457" />
      <inertia ixx="0.0014384" ixy="3.89E-06" ixz="5.22E-05" iyy="0.00164" iyz="-7.1E-07"
        izz="0.00087583" />
    </inertial>
    <visual>
      <origin xyz="0 0 0" rpy="0 0 0" />
      <geometry>
        <mesh filename="/home/lain/robosuite_ws/dual_recovery/robots/meshes/cruzr_s2_v1/R_elbow_yaw_link.STL" />
      </geometry>
      <material name="">
        <color rgba="0.752941176470588 0.752941176470588 0.752941176470588 1" />
      </material>
    </visual>
    <collision>
      <origin xyz="0 0 0" rpy="0 0 0" />
      <geometry>
        <mesh filename="/home/lain/robosuite_ws/dual_recovery/robots/meshes/cruzr_s2_v1/R_elbow_yaw_link.STL" />
      </geometry>
    </collision>
  </link>

  <joint name="R_elbow_yaw_joint" type="revolute">
    <origin xyz="0.019993 -0.10368 0" rpy="1.5708 0 0" />
    <parent link="R_elbow_roll_link" />
    <child link="R_elbow_yaw_link" />
    <axis xyz="0 0 1" />
    <limit lower="-2.9322" upper="2.9322" effort="20" velocity="3.1416" />
  </joint>

  <link name="R_wrist_pitch_link">
    <inertial>
      <origin xyz="-0.038445 0.0048559 0.0047721" rpy="0 0 0" />
      <mass value="1.3145" />
      <inertia ixx="0.00090036" ixy="0.000219" ixz="-0.00022711" iyy="0.0027314" iyz="3.05E-05"
        izz="0.0027358" />
    </inertial>
    <visual>
      <origin xyz="0 0 0" rpy="0 0 0" />
      <geometry>
        <mesh filename="/home/lain/robosuite_ws/dual_recovery/robots/meshes/cruzr_s2_v1/R_wrist_pitch_link.STL" />
      </geometry>
      <material name="">
        <color rgba="0.75294 0.75294 0.75294 1" />
      </material>
    </visual>
    <collision>
      <origin xyz="0 0 0" rpy="0 0 0" />
      <geometry>
        <mesh filename="/home/lain/robosuite_ws/dual_recovery/robots/meshes/cruzr_s2_v1/R_wrist_pitch_link.STL" />
      </geometry>
    </collision>
  </link>

  <joint name="R_wrist_pitch_joint" type="revolute">
    <origin xyz="0 0 0.11832" rpy="3.1416 1.5708 0" />
    <parent link="R_elbow_yaw_link" />
    <child link="R_wrist_pitch_link" />
    <axis xyz="0 0 1" />
    <limit lower="-1.658" upper="1.658" effort="20" velocity="3.1416" />
  </joint>

  <link name="R_wrist_roll_link">
    <inertial>
      <origin xyz="4.63E-06 0.017056 0.0007487" rpy="0 0 0" />
      <mass value="0.1521" />
      <inertia ixx="0.00027356" ixy="0" ixz="-2E-08" iyy="0.00021546" iyz="7.68E-06"
        izz="0.00011023" />
    </inertial>
    <visual>
      <origin xyz="0 0 0" rpy="0 0 0" />
      <geometry>
        <mesh filename="/home/lain/robosuite_ws/dual_recovery/robots/meshes/cruzr_s2_v1/R_wrist_roll_link.STL" />
      </geometry>
      <material name="">
        <color rgba="0.752941176470588 0.752941176470588 0.752941176470588 1" />
      </material>
    </visual>
    <collision>
      <origin xyz="0 0 0" rpy="0 0 0" />
      <geometry>
        <mesh filename="/home/lain/robosuite_ws/dual_recovery/robots/meshes/cruzr_s2_v1/R_wrist_roll_link.STL" />
      </geometry>
    </collision>
  </link>

  <joint name="R_wrist_roll_joint" type="revolute">
    <origin xyz="-0.076 0 0" rpy="1.5708 1.5708 3.1416" />
    <parent link="R_wrist_pitch_link" />
    <child link="R_wrist_roll_link" />
    <axis xyz="0 0 1" />
    <limit lower="-2.0245" upper="2.0245" effort="20" velocity="3.1416" />
  </joint>

  <link name="R_sixforce_link">
    <inertial>
      <origin xyz="-0.00018615 -2.11E-06 -0.011066" rpy="0 0 0" />
      <mass value="0.17" />
      <inertia ixx="3.57E-05" ixy="2.1E-07" ixz="7.8E-07" iyy="5.03E-05" iyz="-6E-08" izz="6.13E-05" />
    </inertial>
    <visual>
      <origin xyz="0 0 0" rpy="0 0 0" />
      <geometry>
        <mesh filename="/home/lain/robosuite_ws/dual_recovery/robots/meshes/cruzr_s2_v1/R_sixforce_link.STL" />
      </geometry>
      <material name="">
        <color rgba="0.698039215686274 0.698039215686274 0.698039215686274 1" />
      </material>
    </visual>
    <collision>
      <origin xyz="0 0 0" rpy="0 0 0" />
      <geometry>
        <mesh filename="/home/lain/robosuite_ws/dual_recovery/robots/meshes/cruzr_s2_v1/R_sixforce_link.STL" />
      </geometry>
    </collision>
  </link>

  <joint name="R_sixforce_joint" type="fixed">
    <origin xyz="0 0.07712 0" rpy="-1.5708 1.5708 0" />
    <parent link="R_wrist_roll_link" />
    <child link="R_sixforce_link" />
    <axis xyz="0 0 0" />
  </joint>
  <link
    name="R_pgc_base_link">
    <inertial>
      <origin
        xyz="-2.46864897094357E-05 0.00101241519250889 0.0801996730801332"
        rpy="0 0 0" />
      <mass
        value="0.512148917198619" />
      <inertia
        ixx="0.000343139195697749"
        ixy="5.50092330982997E-08"
        ixz="-7.25899944571141E-10"
        iyy="0.000325700816895427"
        iyz="2.02321065532314E-06"
        izz="0.000479240940563569" />
    </inertial>
    <visual>
      <origin
        xyz="0 0 0"
        rpy="0 0 0" />
      <geometry>
        <mesh
          filename="/home/lain/robosuite_ws/dual_recovery/robots/meshes/cruzr_s2_v1/pgc_base_link.STL" />
      </geometry>
      <material
        name="">
        <color
          rgba="0.792156862745098 0.819607843137255 0.933333333333333 1" />
      </material>
    </visual>
    <collision>
      <origin
        xyz="0 0 0"
        rpy="0 0 0" />
      <geometry>
        <mesh
          filename="/home/lain/robosuite_ws/dual_recovery/robots/meshes/cruzr_s2_v1/pgc_base_link.STL" />
      </geometry>
    </collision>
  </link>
  <joint name="R_pgc_base_joint" type="fixed">
    <origin xyz="0 0.0 0" rpy="0.0 0 1.5708" />
    <parent link="R_sixforce_link" />
    <child link="R_pgc_base_link" />
    <axis xyz="0 0 0" />
  </joint>
  <link
    name="R_finger1_link">
    <inertial>
      <origin
        xyz="-0.0303858970323615 -0.00381498453417402 -0.00624709492135875"
        rpy="0 0 0" />
      <mass
        value="0.0324239918610202" />
      <inertia
        ixx="2.47261223926961E-06"
        ixy="1.69841580380238E-07"
        ixz="-1.03981478315841E-07"
        iyy="7.85522021789845E-06"
        iyz="-1.88177256558835E-07"
        izz="7.5359499217227E-06" />
    </inertial>
    <visual>
      <origin
        xyz="0 0 0"
        rpy="0 0 0" />
      <geometry>
        <mesh
          filename="/home/lain/robosuite_ws/dual_recovery/robots/meshes/cruzr_s2_v1/finger1_link.STL" />
      </geometry>
      <material
        name="">
        <color
          rgba="0.792156862745098 0.819607843137255 0.933333333333333 1" />
      </material>
    </visual>
    <collision>
      <origin
        xyz="0 0 0"
        rpy="0 0 0" />
      <geometry>
        <mesh
          filename="/home/lain/robosuite_ws/dual_recovery/robots/meshes/cruzr_s2_v1/finger1_link.STL" />
      </geometry>
    </collision>
  </link>
  <joint
    name="R_finger1_joint"
    type="prismatic">
    <origin
      xyz="-0.00016362 -0.018097 0.22048"
      rpy="-1.5708 -1.5708 0" />
    <parent
      link="R_pgc_base_link" />
    <child
      link="R_finger1_link" />
    <axis
      xyz="0 0 1" />
    <limit
      lower="-0.1"
      upper="0.1"
      effort="0"
      velocity="0" />
  </joint>
  <link
    name="R_finger2_link">
    <inertial>
      <origin
        xyz="-0.0303858970296882 -0.00381498453417001 -0.00624709492619996"
        rpy="0 0 0" />
      <mass
        value="0.0324239918610213" />
      <inertia
        ixx="2.47261220318982E-06"
        ixy="1.69841580415508E-07"
        ixz="-1.03981478008923E-07"
        iyy="7.85522021462028E-06"
        iyz="-1.88177256549449E-07"
        izz="7.53594989139987E-06" />
    </inertial>
    <visual>
      <origin
        xyz="0 0 0"
        rpy="0 0 0" />
      <geometry>
        <mesh
          filename="/home/lain/robosuite_ws/dual_recovery/robots/meshes/cruzr_s2_v1/finger2_link.STL" />
      </geometry>
      <material
        name="">
        <color
          rgba="0.792156862745098 0.819607843137255 0.933333333333333 1" />
      </material>
    </visual>
    <collision>
      <origin
        xyz="0 0 0"
        rpy="0 0 0" />
      <geometry>
        <mesh
          filename="/home/lain/robosuite_ws/dual_recovery/robots/meshes/cruzr_s2_v1/finger2_link.STL" />
      </geometry>
    </collision>
  </link>
  <joint
    name="R_finger2_joint"
    type="prismatic">
    <origin
      xyz="0.00013638 0.014376 0.22048"
      rpy="1.5708 -1.5708 0" />
    <parent
      link="R_pgc_base_link" />
    <child
      link="R_finger2_link" />
    <axis
      xyz="0 0 1" />
    <limit
      lower="-0.1"
      upper="0.1"
      effort="0"
      velocity="0" />
  </joint>
</robot>

